Workbook

Sheet Page de garde
B2: CBRE | EMEA | QHSE | Formulaire | RASSa - Evaluation des risques
B3: Evaluation des risques
B5: Nom du compte : | D5: CBRE GWS France SAS
B7: Adresse du site concerné : | D7: 17 quai du Président Paul Doumer - 92400 COURBEVOIE
B9: Périmètre évalué : | D9: Maintenance multitechnique du bâtiment - coordination des entreprises sous-traitantes - Facility management - gestion de projet d'aménagement
B11: Unités de Travail (UT) : Groupement de personnes susceptibles d'être exposées au risque | H11: Cocher les unités de travail évalués
B12: UT 1 : | C12: Equipe administrative (Contract Support, RH, achat, finance, commerce) | H12: x
B13: UT 2 : | C13: Direction générale et opérationnelle (Directeur Général, Directeur Opérationnel, AGM, Responsable Multi-site) | H13: x
B14: UT 3 : | C14: Responsables de site et coordinateurs soft - Contrats à dominante soft | H14: x
B15: UT 4 : | C15: Responsables de site et coordinateurs techniques - Contrats à dominante technique | H15: x
B16: UT 5 : | C16: Techniciens multitechniques | H16: x
B17: UT 6 : | C17: Techniciens frigoristes | H17: x
B18: UT 7 : | C18: Equipiers multi-services (Factotums, Handymans) | H18: x
B19: UT 8 : | C19: Direction Projet / Technique et QHSE | H19: x
B20: UT 9 : | C20: Sous-traitant | H20: x
B22: Version | C22: Objet (contenu de la mise à jour) | E22: Nom de(s) l'évaluateur(s) | G22: Date de mise à jour | H22: Validation Manager
B23: V1 | C23: Mise à jour du Document Unique d'Evaluation des Risques Professionnels | E23: Nicolas Bernard / Islem Resgui / Theo Rocca | G23: 45945
B24: V2 | C24: Présentation, mise à jour,validation | E24: Membres du CSSCT | G24: 46055

Sheet Risk Register
B1: CBRE | EMEA | QHSE | Formulaire | RASSa - Evaluation des risques
B2: Document Unique d'Evaluation des Risques Professionnels
B4: ='Page de garde'!D5 -> CBRE GWS France SAS | M4: Périmètre : | O4: ='Page de garde'!D9 -> Maintenance multitechnique du bâtiment - coordination des entreprises sous-traitantes - Facility management - gestion de projet d'aménagement | AH4: Date de mise à jour : | AI4: ='Page de garde'!G23 -> 45945
B6: ='Page de garde'!D7 -> 17 quai du Président Paul Doumer - 92400 COURBEVOIE | AH6: Par : | AI6: ='Page de garde'!E23 -> Nicolas Bernard / Islem Resgui / Theo Rocca
W7: Mesures de prévention applicables
B8: 1. Sélectionner les principales opérations ou tâches effectuées sur site | C8: 2. Déterminer les tâches exécutées sur site | D8: 3. unités de travail concernées | M8: 4a. Quels sont les principaux risques de cette tâche ? | N8: 4b. Risque INRS | O8: 5. Quels sont les équipements concernés ? | P8: 6. Fonctionnement normal ou dégradé ? | Q8: 7. A quelle fréquence faites vous cette tâche ? | R8: 8. Probabilité qu'un accident survienne | T8: 9. Gravité potentielle | V8: Risque Brute | W8: 10. Spécifier si des éléments de sécurité sont constitutifs de l'équipement | X8: 11. Y a-t-il une règle qui sauvent CBRE qui s'applique à cette tâche ? | Y8: 12. Quels sont les EPC et/ou EPI nécessaire pour effectuer cette tâche ? | Z8: En place ? | AA8: 13. Faut-il avoir suivi des formations/habilitations pour exécuter cette tâche ? | AB8: En place ? | AC8: 14. Y at-il des procédures / protocole à suivre ? Lesquels ? | AD8: En place? | AE8: Risque résiduel - le facteur humain | AG8: Risque net | AH8: 15. Des actions complémentaires sont-elles à prévoir ? Lesquelles ? | AI8: 16. Autre chose ?
B9: Principales opérations / tâches | C9: Facteur d'exposition | D9: UT 1 (adm) | E9: UT2 (DIR / AGM) | F9: UT3 (Coord Soft) | G9: UT4 (Coord Tech) | H9: UT5 (TECH) | I9: UT6 (Frigo) | J9: UT7 (Handyan) | K9: UT8 (PJM / DT QHSE) | L9: UT9 (SST) | M9: Risques | O9: Equipement | P9: Fonctionnement | Q9: Fréquence d'exposition | R9: Probabilité | S9: Score H+I | T9: Gravité | U9: Score 1 | V9: Risk Before Mitigation | W9: Mesures de conception | X9: Règles qui sauvent | Y9: Equipement de protection collectif et individuel | AA9: Formation spécifique | AC9: Mesures organisationnelles | AE9: Alea | AF9: Score 2 | AG9: Risk After Mitigation | AH9: Further risk treatments, controls, mitigation action | AI9: Comment
B10: Travaux électriques | C10: Relamping | H10: x | J10: x | M10: Electrisation / électrocution | N10: 14. Risques liés à l'électricité | O10: Luminaire | P10: dégradé | Q10: 2 | R10: 2 | S10: =Q10+R10 -> 4 | T10: 4 | U10: =VLOOKUP($T10,Cotation!$G$6:$H$10,2,(FALSE)) -> 3 | V10: =HLOOKUP($S10,Cotation!$I$5:$M$10,'Risk Register'!U10,(TRUE)) -> S | W10: Mesure de conception des installations électriques selon norme NFC 15100 | X10: Règle 1 - Autorisation de Travail ( compétence) Regle 2 - Consignation Règle 3 - travaux électrique | Y10: Vêtement de travail ( si possilbe Atex / Arc Flash) Chaussures de sécurité Gants de manipulation fine Kit de consignation VAT Balisage de la zone si travail en hauteur | Z10: 0.25 | AA10: Habilitation électrique niveau BS à minima | AB10: 0.25 | AC10: Consignation des énergies préalable au niveau du disjoncteur Loto - condamnation du départ éléctrique Permis de travail électrique EA : Verification de compétence electrique | AD10: 0.25 | AE10: =100%-(Z10+AB10+AD10) -> 0.25 | AF10: =S10*AE10 -> 1 | AG10: =HLOOKUP($AF10,Cotation!$I$5:$M$10,'Risk Register'!U10,(TRUE)) -> M
B11: Travaux électriques | C11: Réarmement de disjoncteur | G11: x | H11: x | J11: x | M11: Electrisation / électrocution | N11: 14. Risques liés à l'électricité | O11: Armoire électrique | P11: dégradé | Q11: 3 | R11: 1 | S11: =Q11+R11 -> 4 | T11: 4 | U11: =VLOOKUP($T11,Cotation!$G$6:$H$10,2,(FALSE)) -> 3 | V11: =HLOOKUP($S11,Cotation!$I$5:$M$10,'Risk Register'!U11,(TRUE)) -> S | W11: Mesure de conception des installations électriques selon norme NFC 15100 | X11: Règle 1 - Autorisation de Travail ( compétence) | Y11: Vêtement de travail Chaussures de sécurité Gants Casque électricien | Z11: 0.25 | AA11: minimum l'habilitation BE Manœuvre ou l'habilitation BS | AB11: 0.25 | AC11: EA : Verification de compétence electriq | AD11: 0.25 | AE11: =100%-(Z11+AB11+AD11) -> 0.25 | AF11: =S11*AE11 -> 1 | AG11: =HLOOKUP($AF11,Cotation!$I$5:$M$10,'Risk Register'!U11,(TRUE)) -> M
B12: Conduite de véhicule | C12: Circulation en voiture / camionnette | D12: x | E12: x | F12: x | G12: x | H12: x | I12: x | J12: x | K12: x | L12: x | M12: Accident de la route | N12: Risques routiers en mission | O12: VL | P12: Normal | Q12: 5 | R12: 4 | S12: =Q12+R12 -> 9 | T12: 5 | U12: =VLOOKUP($T12,Cotation!$G$6:$H$10,2,(FALSE)) -> 2 | V12: =HLOOKUP($S12,Cotation!$I$5:$M$10,'Risk Register'!U12,(TRUE)) -> C | W12: Sécurité intrinsinque des VL | X12: Règle 4 - Conduite | Y12: Sécurité des véhicules (ceinture de sécurité) | Z12: 0.25 | AA12: Formation aux risques routiers | AB12: 0 | AC12: Code de la route applicable à tous Charte de conduite de vehicule CBRE Maintenance des véhicules CBRE - Contrat de "full maintenance" intégré - Contrat intégrant pneumatiques été/hiver | AD12: 0.25 | AE12: =100%-(Z12+AB12+AD12) -> 0.5 | AF12: =S12*AE12 -> 4.5 | AG12: =HLOOKUP($AF12,Cotation!$I$5:$M$10,'Risk Register'!U17,(TRUE)) -> S | AH12: Procédure de vérification (checklist) des véhicules à réaliser par les managers à remettreen place | AI12: Politique de déplacements - Limiter les déplacements et favoriser les visio conférence - Favoriser les déplacements par les transports en commun (train)
B13: Travaux administratifs | C13: Travail sur écran | D13: x | E13: x | F13: x | G13: x | H13: x | I13: x | J13: x | K13: x | L13: x | M13: Fatigue visuelle / TMS | N13: 18. Risques liés au travail sur écran | O13: Ordinateur / écran / caliver et souris | P13: Normal | Q13: 5 | R13: 2 | S13: =Q13+R13 -> 7 | T13: 2 | U13: =VLOOKUP($T13,Cotation!$G$6:$H$10,2,(FALSE)) -> 5 | V13: =HLOOKUP($S13,Cotation!$I$5:$M$10,'Risk Register'!U13,(TRUE)) -> M | W13: Ergonomie des bureaux et chaise ergonomique | X13: non | Y13: Matériel bureautique ergonomique | Z13: 0.25 | AA13: Atelier d'ergonomie Core Safety Training : elearning | AB13: 0.1 | AC13: Non | AD13: 0 | AE13: =100%-(Z13+AB13+AD13) -> 0.65 | AF13: =S13*AE13 -> 4.55 | AG13: =HLOOKUP($AF13,Cotation!$I$5:$M$10,'Risk Register'!U14,(TRUE)) -> M
B14: Manutention manuelle | C14: Ouverture de trappes et regards | H14: x | I14: x | J14: x | M14: Coupure / ecrasement / TMS | N14: 05. Risques liés à la manutention manuelle de charge | O14: Trappes et regards | P14: Normal | Q14: 1 | R14: 2 | S14: =Q14+R14 -> 3 | T14: 3 | U14: =VLOOKUP($T14,Cotation!$G$6:$H$10,2,(FALSE)) -> 4 | V14: =HLOOKUP($S14,Cotation!$I$5:$M$10,'Risk Register'!U14,(TRUE)) -> M | W14: Conception des trappes variable selon age matériaux et utilité | X14: non | Y14: Gants de manutention lourde Chaussure de sécurité Outils de levage Balisage de la zone de travail. | Z14: 0.1 | AA14: Core Safety Training : elearning | AB14: 0 | AC14: Analyse de risque dynmaique ou RAD Check list manutention manuelle MANHa Préférez l'utilisation d'outil de levage spécifique (lève plaque, pioche…) Ne jamais laisser une plaque ouverte sans balisage | AD14: 0 | AE14: =100%-(Z14+AB14+AD14) -> 0.9 | AF14: =S14*AE14 -> 2.7 | AG14: =HLOOKUP($AF14,Cotation!$I$5:$M$10,'Risk Register'!U20,(TRUE)) -> M
B15: Manutention manuelle | C15: Déménagement de meubles | H15: x | I15: x | J15: x | M15: TMS / heurt / choc / ecrasement | N15: 05. Risques liés à la manutention manuelle de charge | O15: Mobilier | P15: Normal | Q15: 5 | R15: 4 | S15: =Q15+R15 -> 9 | T15: 3 | U15: =VLOOKUP($T15,Cotation!$G$6:$H$10,2,(FALSE)) -> 4 | V15: =HLOOKUP($S15,Cotation!$I$5:$M$10,'Risk Register'!U13,(TRUE)) -> S | W15: non | X15: non | Y15: Gants de manutention Chaussure de sécurité | Z15: 0.25 | AA15: Formation gestes et postures Core Safety Training : elearning | AB15: 0.25 | AC15: Analyse de risque dynmaique ou RAD Check list manutention manuelle MANHa Travail à deux pour le mobilier volumineux Utilitation des moyens mécaniques de manutention (chariots, transpalettes, véhicules…) Outils spécifique de levage hors equpement necessitant formation spécifique (CACES) | AD15: 0.25 | AE15: =100%-(Z15+AB15+AD15) -> 0.25 | AF15: =S15*AE15 -> 2.25 | AG15: =HLOOKUP($AF15,Cotation!$I$5:$M$10,'Risk Register'!U13,(TRUE)) -> F
B16: Utilisation d'outils électroportatif | C16: Meulage | G16: x | M16: Coupure / incendie / projection de matière | N16: 13. Risques d'incendie, d'explosion | O16: Meuleuse / disqueuse | P16: Normal | Q16: 2 | R16: 2 | S16: =Q16+R16 -> 4 | T16: 2 | V16: =HLOOKUP($S16,Cotation!$I$5:$M$10,'Risk Register'!U18,(TRUE)) -> F | W16: Outils munis de capot / carter deprotection sur autour de la lame et d'une poignée | X16: Règle 1 - Autorisation de Travail ( compétence) Regle 7 - travail par point chaud | Y16: Gants anticoupure Ecran facial Vêtements de travail balisage de la zone de travail extincteur | AA16: Core safety training : elearning Formation PTW : Travauxparpoint chaud Formation extincteur | AC16: Permis de travail signé Procedure hot work Procedure PTW : Permis Feu Vérification préalable du matériel (verification avant utilisation / inspection annuelle) Choix préalable du disque le plus adaptée au matériau découpé Interdiction d'enlever la poignée | AD16: 0.25 | AE16: =100%-(Z16+AB16+AD16) -> 0.75 | AF16: =S16*AE16 -> 3 | AG16: =HLOOKUP($AF16,Cotation!$I$5:$M$10,'Risk Register'!U18,(TRUE)) -> F
B17: Utilisation d'outils électroportatif | C17: Meulage | H17: x | I17: x | J17: x | M17: Coupure / incendie / projection de matière | N17: 13. Risques d'incendie, d'explosion | O17: Meuleuse / disqueuse | P17: Normal | Q17: 2 | R17: 2 | S17: =Q17+R17 -> 4 | T17: 4 | U17: =VLOOKUP($T17,Cotation!$G$6:$H$10,2,(FALSE)) -> 3 | V17: =HLOOKUP($S17,Cotation!$I$5:$M$10,'Risk Register'!U19,(TRUE)) -> M | W17: Outils munis de capot / carter deprotection sur autour de la lame et d'une poignée | X17: Règle 1 - Autorisation de Travail ( compétence) Regle 7 - travail par point chaud | Y17: Gants anticoupure Ecran facial Vêtements de travail balisage de la zone de travail extincteur | Z17: 0.25 | AA17: Core safety training : elearning | AB17: 0 | AC17: Permis de travail signé Procedure hot work Procedure PTW : Permis Feu Vérification préalable du matériel (verification avant utilisation / inspection annuelle) Choix préalable du disque le plus adaptée au matériau découpé Interdiction d'enlever la poignée | AD17: 0.25 | AE17: =100%-(Z17+AB17+AD17) -> 0.5 | AF17: =S17*AE17 -> 2 | AG17: =HLOOKUP($AF17,Cotation!$I$5:$M$10,'Risk Register'!U19,(TRUE)) -> M
B18: Travaux en hauteur | C18: Travail sur escabeau | G18: x | M18: Chute de hauteur Basculement de l'escabeau Chute d'objet | N18: 02. Risques de chutes de hauteur | O18: Escabeau | P18: Normal | Q18: 3 | R18: 2 | S18: =Q18+R18 -> 5 | T18: 1 | U18: =VLOOKUP($T18,Cotation!$G$6:$H$10,2,(FALSE)) -> 6 | V18: =HLOOKUP($S18,Cotation!$I$5:$M$10,'Risk Register'!U22,(TRUE)) -> S | W18: Escabeau conforme EN 131 (pas de défault structurel, présence des patins anti-dérapant) | X18: Règle 1 - Autorisation de Travail ( compétence) Regle 5 - Travail en hauteur | Y18: Casquette coquée Chaussure de sécurité Gants Lunettes de sécurité Balisage de la zone | Z18: 0.25 | AA18: Core safety training : elearning Formation PTW : Travaux en hauteur au dessus de 1,8 m | AB18: 0 | AC18: Analyse de risque avant travaux ou RAD Inspection escabeau aavnt utilisation Inspection mensuelle WAHSa Privilégier l'utilisation d'une pirl lorsque c'est possible. Vérification de l'équipement avant utilisation (état de conservation, présence de l'ensemble des pièces, stabilité) Matériel ressencé et référencé Permis de travail en hauteur pour les hauteurs de plus de 1,80 signé EA : verification des compétences | AD18: 0.1 | AE18: =100%-(Z18+AB18+AD18) -> 0.65 | AF18: =S18*AE18 -> 3.25 | AG18: =HLOOKUP($AF18,Cotation!$I$5:$M$10,'Risk Register'!U22,(TRUE)) -> M
B19: Travaux en hauteur | C19: Travail sur escabeau | H19: x | I19: x | J19: x | M19: Chute de hauteur Basculement de l'escabeau Chute d'objet | N19: 02. Risques de chutes de hauteur | O19: Escabeau | P19: Normal | Q19: 3 | R19: 4 | S19: =Q19+R19 -> 7 | T19: 3 | U19: =VLOOKUP($T19,Cotation!$G$6:$H$10,2,(FALSE)) -> 4 | V19: =HLOOKUP($S19,Cotation!$I$5:$M$10,'Risk Register'!U23,(TRUE)) -> S | W19: Escabeau conforme EN 131 (pas de défault structurel, présence des patins anti-dérapant) | X19: Règle 1 - Autorisation de Travail ( compétence) Regle 5 - Travail en hauteur | Y19: Casquette coquée Chaussure de sécurité Gants Lunettes de sécurité Balisage de la zone | Z19: 0.25 | AA19: Core safety training :travail en hauteur | AB19: 0 | AC19: Analyse de risque avant travaux ou RAD Privilégier l'utilisation d'une pirl lorsque c'est possible. Vérification de l'équipement avant utilisation (état de conservation, présence de l'ensemble des pièces, stabilité) Matériel ressencé et référencé Permis de travail en hauteur pour les hauteurs de plus de 1,8m signé EA : verification des compétences | AD19: 0.1 | AE19: =100%-(Z19+AB19+AD19) -> 0.65 | AF19: =S19*AE19 -> 4.55 | AG19: =HLOOKUP($AF19,Cotation!$I$5:$M$10,'Risk Register'!U23,(TRUE)) -> S
B20: Travaux électriques | C20: Remplacement de disjoncteur dans une armoire électrique BT | G20: x | H20: x | I20: x | M20: Electrisation / électrocution | N20: 14. Risques liés à l'électricité | O20: Armoire électrique | P20: dégradé | Q20: 2 | R20: 2 | S20: =Q20+R20 -> 4 | T20: 4 | U20: =VLOOKUP($T20,Cotation!$G$6:$H$10,2,(FALSE)) -> 3 | V20: =HLOOKUP($S20,Cotation!$I$5:$M$10,'Risk Register'!U10,(TRUE)) -> S | W20: Mesure de conception des installations électriques selon norme NFC 15100 | X20: Règle 1 - Autorisation de Travail ( compétence) Regle 2 - Consignation Règle 3 - travaux électrique | Y20: Casque électricien Gants électricien Vêtement de travail (arc flash et Atex si possible) Chaussures de sécurité Tapis isolant Kit de consignation VAT Balisage | Z20: 0.25 | AA20: Tous : Habilitation électrique niveau BR à minima Coordinateur : Formation PTW travaux electrique | AB20: 0.25 | AC20: Analyse de risque dynmaique ou RAD Permis de travail electrique signé Consignation des énergies EA : verification des compétences | AD20: 0.25 | AE20: =100%-(Z20+AB20+AD20) -> 0.25 | AF20: =S20*AE20 -> 1 | AG20: =HLOOKUP($AF20,Cotation!$I$5:$M$10,'Risk Register'!U10,(TRUE)) -> M
B21: Travaux électriques | C21: Maintenance electrique BT | G21: x | H21: x | I21: x | M21: Electrisation / électrocution | N21: 14. Risques liés à l'électricité | O21: Equipement électrique | P21: Normal | Q21: 3 | R21: 1 | S21: =Q21+R21 -> 4 | T21: 4 | U21: =VLOOKUP($T21,Cotation!$G$6:$H$10,2,(FALSE)) -> 3 | V21: =HLOOKUP($S21,Cotation!$I$5:$M$10,'Risk Register'!U21,(TRUE)) -> S | W21: Mesure de conception des installations électriques selon norme NFC 15100 | X21: Règle 1 - Autorisation de Travail ( compétence) Regle 2 - Consignation Règle 3 - travaux électrique | Y21: Casque électricien Gants électricien Vêtement de travail (arc flash et Atex si possible) Chaussures de sécurité Tapis isolant Kit de consignation VAT Balisage | Z21: 0.25 | AA21: Tous : Habilitation électrique niveau BR à minima Coordinateur : Formation PTW travaux electrique | AB21: 0.25 | AC21: Analyse de risque dynmaique ou RAD Permis de travail electrique signé Consignation des énergies EA : verification des compétences | AD21: 0.25 | AE21: =100%-(Z21+AB21+AD21) -> 0.25 | AF21: =S21*AE21 -> 1 | AG21: =HLOOKUP($AF21,Cotation!$I$5:$M$10,'Risk Register'!U11,(TRUE)) -> M
B22: Travaux électriques | C22: Recherche de panne électrique | G22: x | H22: x | I22: x | M22: Electrisation / électrocution | N22: 14. Risques liés à l'électricité | O22: Tout équipement électrique | P22: dégradé | Q22: 4 | R22: 3 | S22: =Q22+R22 -> 7 | T22: 4 | U22: =VLOOKUP($T22,Cotation!$G$6:$H$10,2,(FALSE)) -> 3 | V22: =HLOOKUP($S22,Cotation!$I$5:$M$10,'Risk Register'!U15,(TRUE)) -> S | W22: Mesure de conception des installations électriques selon norme NFC 15100 | X22: Règle 1 - Autorisation de Travail ( compétence) Regle 2 - Consignation Règle 3 - travaux électrique | Y22: Casque électricien Gants électricien Vêtement de travail (arc flash et Atex si possible) Chaussures de sécurité Tapis isolant Kit de consignation VAT Balisage | Z22: 0.25 | AA22: Habilitation électrique niveau BR à minima Coordinateur : Formation PTW travaux electrique | AB22: 0.25 | AC22: Analyse de risque dynmaique ou RAD Permis de travail electrique signé Consignation des énergies EA : verification des compétences | AD22: 0.25 | AE22: =100%-(Z22+AB22+AD22) -> 0.25 | AF22: =S22*AE22 -> 1.75 | AG22: =HLOOKUP($AF22,Cotation!$I$5:$M$10,'Risk Register'!U15,(TRUE)) -> F
B23: Travaux en hauteur | C23: Travail sur nacelle élévatrice | G23: x | H23: x | I23: x | M23: Chute de hauteur Chute d'objet | N23: 02. Risques de chutes de hauteur | O23: Nacelle élévatrice | P23: Normal | Q23: 2 | R23: 1 | S23: =Q23+R23 -> 3 | T23: 4 | U23: =VLOOKUP($T23,Cotation!$G$6:$H$10,2,(FALSE)) -> 3 | V23: =HLOOKUP($S23,Cotation!$I$5:$M$10,'Risk Register'!U22,(TRUE)) -> M | W23: Equipement conforme et CE | X23: Règle 1 - Autorisation de Travail ( compétence) Regle 6 - Travail en hauteur | Y23: Casque avec jugulaire Chaussure de sécurité gants de travail équipement de protection contre les chute de hauteur (harnais et longe sans absorbeur) Balisage de la zone de travail | Z23: 0.25 | AA23: Formation nacelle : - CACES 486 A linéaire - CACES 486 B mouvements horizontaux ou une rotation Formation port du harnais Coordinateur : Formation PTW travail en hauteur | AB23: 0.25 | AC23: Analyse de risque dynmaique ou RAD Permis de travail en hauteur signé EA : verification des compétences | AD23: 0.25 | AE23: =100%-(Z23+AB23+AD23) -> 0.25 | AF23: =S23*AE23 -> 0.75 | AG23: =HLOOKUP($AF23,Cotation!$I$5:$M$10,'Risk Register'!U22,(TRUE)) -> M
B24: Travaux mécaniques | C24: Remplacement de courroies moteur extracteur d'air | G24: x | H24: x | M24: Electrisation / électrocution Coupure / heurt | N24: 14. Risques liés à l'électricité | O24: Extracteur d'air | P24: dégradé | Q24: 1 | R24: 1 | S24: =Q24+R24 -> 2 | T24: 3 | U24: =VLOOKUP($T24,Cotation!$G$6:$H$10,2,(FALSE)) -> 4 | V24: =HLOOKUP($S24,Cotation!$I$5:$M$10,'Risk Register'!U24,(TRUE)) -> M | W24: non | X24: Règle 1 - Autorisation de Travail ( compétence) Regle 2 - Consignation Règle 3 - travaux électrique | Y24: Casque / Chaussure de sécurité / gants de travail / lunettes de sécurité Kit de consignation Balisage de la zone de travail | Z24: 0.25 | AA24: Habiitation BR pour les consignations électriques | AB24: 0.25 | AC24: Analyse de risque dynmaique ou RAD Permis de travail electrique signé Consignation des énergies EA : verification des compétences | AD24: 0.25 | AE24: =100%-(Z24+AB24+AD24) -> 0.25 | AF24: =S24*AE24 -> 0.5 | AG24: =HLOOKUP($AF24,Cotation!$I$5:$M$10,'Risk Register'!U24,(TRUE)) -> F
B25: Travaux mécaniques | C25: Remplacement de filtre CTA | G25: x | H25: x | I25: x | M25: Manutention | N25: 09. Risques liés aux équipements de travail | O25: CTA | P25: dégradé | Q25: 4 | R25: 2 | S25: =Q25+R25 -> 6 | T25: 2 | U25: =VLOOKUP($T25,Cotation!$G$6:$H$10,2,(FALSE)) -> 5 | V25: =HLOOKUP($S25,Cotation!$I$5:$M$10,'Risk Register'!U25,(TRUE)) -> M | W25: Refixer systéatiquement des capôts et boulonneries | X25: Règle 1 - Autorisation de Travail ( compétence) Regle 2 - Consignation | Y25: Casque / Chaussure de sécurité / gants de travail / lunettes de sécurité Kit de consignation Balisage de la zone de travail | Z25: 0.25 | AA25: non | AB25: 0 | AC25: Analyse de risque dynmaique ou RAD Arrêt préalable de la CTA au commutateur avec cadenas Test de redemarage Vérification prélabale des outillages | AD25: 0.25 | AE25: =100%-(Z25+AB25+AD25) -> 0.5 | AF25: =S25*AE25 -> 3 | AG25: =HLOOKUP($AF25,Cotation!$I$5:$M$10,'Risk Register'!U25,(TRUE)) -> F
B26: Travaux électriques | C26: Mesure d'intensité | G26: x | H26: x | I26: x | M26: Electrisation / electrocution | N26: 14. Risques liés à l'électricité | O26: Equipement électrique | P26: Normal | Q26: 3 | R26: 1 | S26: =Q26+R26 -> 4 | T26: 4 | U26: =VLOOKUP($T26,Cotation!$G$6:$H$10,2,(FALSE)) -> 3 | V26: =HLOOKUP($S26,Cotation!$I$5:$M$10,'Risk Register'!U26,(TRUE)) -> S | W26: Mesure de conception des installations électriques selon norme NFC 15100 | X26: Règle 1 - Autorisation de Travail ( compétence) Regle 3 - travaux electriques | Y26: Casque électricien Gants électricien Vêtement de travail ( Atex et Arc Flach si possible) Multimètre | Z26: 0.25 | AA26: Habilitation électrique niveau BR à minima Coordinateur : Formation PTW travaux electrique | AB26: 0.25 | AC26: Permis de travail électrique signé Repérage des plans Etiquetage Suivi des modes opératoires | AD26: 0.25 | AE26: =100%-(Z26+AB26+AD26) -> 0.25 | AF26: =S26*AE26 -> 1 | AG26: =HLOOKUP($AF26,Cotation!$I$5:$M$10,'Risk Register'!U26,(TRUE)) -> M
B27: Relevés et mesures | C27: Relevé de compteur | G27: x | H27: x | I27: x | J27: x | M27: Ecrasement des mains/ pieds | N27: 09. Risques liés aux équipements de travail | O27: Plaque / couvercle de regard | P27: Normal | Q27: 1 | R27: 2 | S27: =Q27+R27 -> 3 | T27: 3 | U27: =VLOOKUP($T27,Cotation!$G$6:$H$10,2,(FALSE)) -> 4 | V27: =HLOOKUP($S27,Cotation!$I$5:$M$10,'Risk Register'!U27,(TRUE)) -> M | W27: non | Y27: Casque / casquette coquéex Chaussures de sécurité gants de manutention Lunette de sécurité Outil de levage de plaque | Z27: 0.25 | AA27: Gestes et postures | AB27: 0.25 | AD27: 0.25 | AE27: =100%-(Z27+AB27+AD27) -> 0.25 | AF27: =S27*AE27 -> 0.75 | AG27: =HLOOKUP($AF27,Cotation!$I$5:$M$10,'Risk Register'!U27,(TRUE)) -> F
B28: Travaux mécaniques | C28: Montage / démontage de brides | G28: x | H28: x | I28: x | J28: x | M28: Projection de liquide / choc heurt / pincement / chute d'objet / gestes et postures | N28: 09. Risques liés aux équipements de travail | O28: Canalisation | P28: dégradé | Q28: 1 | R28: 2 | S28: =Q28+R28 -> 3 | T28: 2 | U28: =VLOOKUP($T28,Cotation!$G$6:$H$10,2,(FALSE)) -> 5 | V28: =HLOOKUP($S28,Cotation!$I$5:$M$10,'Risk Register'!U28,(TRUE)) -> F | W28: non | X28: Règle 1 - Autorisation de Travail ( compétence) Regle 2 - Consignation | Y28: Casque / casquette coquéex Chaussures de sécurité gants de manutention Lunette de sécurité | Z28: 0.25 | AA28: Habiitation BR pour les consignations électriques | AB28: 0.25 | AC28: Autorisation prélable aux travaux de démontage Consignation préalable des équipements électriques Fermeture et condamnation des vannes / purge des réseaux Elemination des energies residuelles Vérification prélabale des outillages | AD28: 0.25 | AE28: =100%-(Z28+AB28+AD28) -> 0.25 | AF28: =S28*AE28 -> 0.75 | AG28: =HLOOKUP($AF28,Cotation!$I$5:$M$10,'Risk Register'!U28,(TRUE)) -> F
B29: Travaux mécaniques | C29: Travaux mécaniques sur tuyauterie - remplacement de vanne par exemple | G29: x | H29: x | I29: x | J29: x | M29: Projection de liquide / choc heurt / pincement / chute d'objet / electrisation / gestes et postures | N29: 09. Risques liés aux équipements de travail | O29: Canalisation | P29: dégradé | Q29: 1 | R29: 2 | S29: =Q29+R29 -> 3 | T29: 2 | U29: =VLOOKUP($T29,Cotation!$G$6:$H$10,2,(FALSE)) -> 5 | V29: =HLOOKUP($S29,Cotation!$I$5:$M$10,'Risk Register'!U29,(TRUE)) -> F | W29: non | X29: Règle 1 - Autorisation de Travail ( compétence) Regle 2 - Consignation | Y29: Casque / Chaussure de sécurité / gants de travail / lunettes de sécurité Kit de consignation Balisage de la zone de travail | Z29: 0.25 | AA29: non | AB29: 0 | AC29: Autorisation prélable aux travaux de démontage Consignation préalable des équipements électriques Fermeture et condamnation des vannes / purge des réseaux Elemination des energies residuelles Vérification prélabale des outillages | AD29: 0.25 | AE29: =100%-(Z29+AB29+AD29) -> 0.5 | AF29: =S29*AE29 -> 1.5 | AG29: =HLOOKUP($AF29,Cotation!$I$5:$M$10,'Risk Register'!U29,(TRUE)) -> F
B30: Travaux électriques | C30: Raccordement électrique | G30: x | H30: x | M30: Electrisation / électrocution | N30: 14. Risques liés à l'électricité | O30: Câble / Matériel électrique | P30: Normal | Q30: 3 | R30: 3 | S30: =Q30+R30 -> 6 | T30: 4 | U30: =VLOOKUP($T30,Cotation!$G$6:$H$10,2,(FALSE)) -> 3 | V30: =HLOOKUP($S30,Cotation!$I$5:$M$10,'Risk Register'!U30,(TRUE)) -> S | W30: Mesure de conception des installations électriques selon norme NFC 15100 | X30: Règle 1 - Autorisation de Travail ( compétence) Regle 2 - Consignation Règle 3 - travaux électrique | Y30: Casque électricien Gants électricien Vêtement de travail (arc flash et Atex si possible) Chaussures de sécurité Tapis isolant Kit de consignation VAT Balisage | Z30: 0.25 | AA30: Habilitation B1 minimum Coordinateur : Formation PTW travaux electrique | AB30: 0.25 | AC30: Analyse de risque dynmaique ou RAD Permis de travail electrique signé Consignation des énergies EA : verification des compétences | AD30: 0.25 | AE30: =100%-(Z30+AB30+AD30) -> 0.25 | AF30: =S30*AE30 -> 1.5 | AG30: =HLOOKUP($AF30,Cotation!$I$5:$M$10,'Risk Register'!U30,(TRUE)) -> M
B31: Travaux électriques | C31: Remplacement d'intérrupteur / remplacement de prise | H31: x | M31: Electrisation / électrocution | N31: 14. Risques liés à l'électricité | O31: Prise / interrupteur | P31: Normal | Q31: 3 | R31: 3 | S31: =Q31+R31 -> 6 | T31: 4 | U31: =VLOOKUP($T31,Cotation!$G$6:$H$10,2,(FALSE)) -> 3 | V31: =HLOOKUP($S31,Cotation!$I$5:$M$10,'Risk Register'!U31,(TRUE)) -> S | W31: Mesure de conception des installations électriques selon norme NFC 15100 | X31: Règle 1 - Autorisation de Travail ( compétence) Regle 2 - Consignation Règle 3 - travaux électrique | Y31: Casque électricien Gants électricien Vêtement de travail (arc flash et Atex si possible) Chaussures de sécurité Tapis isolant Kit de consignation VAT Balisage | Z31: 0.25 | AA31: Habilitation BS minimum Coordinateur : Formation PTW travaux electrique | AB31: 0.25 | AC31: Analyse de risque dynmaique ou RAD Permis de travail electrique signé Consignation des énergies EA : verification des compétences | AD31: 0.25 | AE31: =100%-(Z31+AB31+AD31) -> 0.25 | AF31: =S31*AE31 -> 1.5 | AG31: =HLOOKUP($AF31,Cotation!$I$5:$M$10,'Risk Register'!U31,(TRUE)) -> M
B32: Bricolage | C32: Travaux de serrurerie | G32: x | H32: x | J32: x | M32: Coupure / heurt | N32: 09. Risques liés aux équipements de travail | O32: Outillage manuel ou électroportatif | P32: Normal | Q32: 2 | R32: 3 | S32: =Q32+R32 -> 5 | T32: 2 | U32: =VLOOKUP($T32,Cotation!$G$6:$H$10,2,(FALSE)) -> 5 | V32: =HLOOKUP($S32,Cotation!$I$5:$M$10,'Risk Register'!U32,(TRUE)) -> M | W32: N/A | X32: non | Y32: Chaussures de sécurité / Gants de manutention / Lunettes de sécurité | Z32: 0.25 | AA32: Non | AB32: 0 | AC32: Analyse de risque préalbale et vérification du bon fonctionnement et de la présence de tout les éléments de sécurité sur les outils | AD32: 0.25 | AE32: =100%-(Z32+AB32+AD32) -> 0.5 | AF32: =S32*AE32 -> 2.5 | AG32: =HLOOKUP($AF32,Cotation!$I$5:$M$10,'Risk Register'!U32,(TRUE)) -> F
B33: Bricolage | C33: Montage / démontage de meuble | G33: x | H33: x | J33: x | M33: Coupure / heurt | N33: 05. Risques liés à la manutention manuelle de charge | O33: Mobilier / outillage manuel ou électroportaif | P33: Normal | Q33: 3 | R33: 2 | S33: =Q33+R33 -> 5 | T33: 3 | U33: =VLOOKUP($T33,Cotation!$G$6:$H$10,2,(FALSE)) -> 4 | V33: =HLOOKUP($S33,Cotation!$I$5:$M$10,'Risk Register'!U33,(TRUE)) -> M | W33: N/A | X33: non | Y33: Chaussures de sécurité / Gants de manutention / Lunettes de sécurité | Z33: 0.25 | AA33: Formation gestes et postures | AB33: 0.1 | AC33: Procédure manual handling | AD33: 0.1 | AE33: =100%-(Z33+AB33+AD33) -> 0.55 | AF33: =S33*AE33 -> 2.75 | AG33: =HLOOKUP($AF33,Cotation!$I$5:$M$10,'Risk Register'!U33,(TRUE)) -> M
B34: Relevés et mesures | C34: Recherche de fuite sur groupe froid | I34: x | N34: 14. Risques liés à l'électricité | O34: Groupe Froid | P34: Normal | Q34: 2 | R34: 1 | S34: =Q34+R34 -> 3 | T34: 2 | U34: =VLOOKUP($T34,Cotation!$G$6:$H$10,2,(FALSE)) -> 5 | V34: =HLOOKUP($S34,Cotation!$I$5:$M$10,'Risk Register'!U34,(TRUE)) -> F | W34: Sonde de détection fixesur les groupe de capacité supérieur à 500KG | X34: Règle 1 - Autorisation de Travail ( compétence) Regle 2 - Consignation Règle 3 - travaux électrique | Y34: Vêtement de travail couvrant Gants de protection chimique vérifier les EPI recommandés de la FDS au préalable Rubrique 8 / Lunette de sécurité. | Z34: 0.25 | AA34: Habilitation BS minimum Etre titulaire d'une attestation de capacité de niveau I pour les frigoriste | AB34: 0.25 | AC34: Analyse de risque dynmaique ou RAD Permis de travail electrique signé Consignation des énergies EA : verification des compétences | AD34: 0.25 | AE34: =100%-(Z34+AB34+AD34) -> 0.25 | AF34: =S34*AE34 -> 0.75 | AG34: =HLOOKUP($AF34,Cotation!$I$5:$M$10,'Risk Register'!U34,(TRUE)) -> F
B35: Exposition aux produits chimiques | C35: Remplacement de fluide frigorigène | I35: x | M35: Projection de produits chimiques / Inhalation de vapeurs chimiques / brûlure | N35: 07. Risques liés aux produits chimiques, aux émissions et aux déchets | O35: Fluide frigorigène | P35: Normal | Q35: 1 | R35: 1 | S35: =Q35+R35 -> 2 | T35: 3 | U35: =VLOOKUP($T35,Cotation!$G$6:$H$10,2,(FALSE)) -> 4 | V35: =HLOOKUP($S35,Cotation!$I$5:$M$10,'Risk Register'!U35,(TRUE)) -> M | W35: non | X35: non | Y35: Vêtement de travail couvrant Gants de protection chimique vérifier les EPI recommandés de la FDS au préalable Rubrique 8 Lunette de sécurité. | Z35: 0.25 | AA35: Etre titulaire d'une attestation de capacité de niveau I pour les frigoriste | AB35: 0.25 | AC35: FDS des produits utilisés Procedure substance dangeureuse COSH Alayse de risque produit chimique Seirich Respect strict des consignes de tri Attention aux mélange de déchets incompatibles Déclaration aux autorités des quantités par type de fluide évacué | AD35: 0.25 | AE35: =100%-(Z35+AB35+AD35) -> 0.25 | AF35: =S35*AE35 -> 0.5 | AG35: =HLOOKUP($AF35,Cotation!$I$5:$M$10,'Risk Register'!U35,(TRUE)) -> F
B36: Exposition aux produits chimiques | C36: Manipulation de déchets dangereux | H36: x | I36: x | J36: x | M36: Projection de produits chimiques / Inhalation de vapeurs chimiques / brûlure | N36: 07. Risques liés aux produits chimiques, aux émissions et aux déchets | O36: Déchets dangereux | P36: Normal | Q36: 2 | R36: 1 | S36: =Q36+R36 -> 3 | T36: 3 | U36: =VLOOKUP($T36,Cotation!$G$6:$H$10,2,(FALSE)) -> 4 | V36: =HLOOKUP($S36,Cotation!$I$5:$M$10,'Risk Register'!U36,(TRUE)) -> M | W36: non | X36: non | Y36: Vêtement de travail couvrant Gants de protection chimique vérifier les EPI recommandés de la FDS au préalable Rubrique 8 Lunette de sécurité. | Z36: 0.25 | AA36: Coresafety training : Sensibilisation à la manipulation des produits chimiques | AB36: 0.25 | AC36: FDS des produits utilisés Alayse de risque produit chimique Seirich Respect strict des consignes de tri Attention aux mélange de déchets incompatibles Déclaration aux autorités des quantités par type de dechets | AD36: 0.25 | AE36: =100%-(Z36+AB36+AD36) -> 0.25 | AF36: =S36*AE36 -> 0.75 | AG36: =HLOOKUP($AF36,Cotation!$I$5:$M$10,'Risk Register'!U36,(TRUE)) -> F
B37: Exposition aux produits chimiques | C37: Stockage de déchets liquides dangereux | H37: x | I37: x | J37: x | M37: Projection de produits chimiques / Inhalation de vapeurs chimiques / brûlure | N37: 07. Risques liés aux produits chimiques, aux émissions et aux déchets | O37: Liquides et produits chimiques étiquetés dangereux | P37: Normal | Q37: 2 | R37: 1 | S37: =Q37+R37 -> 3 | T37: 3 | U37: =VLOOKUP($T37,Cotation!$G$6:$H$10,2,(FALSE)) -> 4 | V37: =HLOOKUP($S37,Cotation!$I$5:$M$10,'Risk Register'!U37,(TRUE)) -> M | W37: non | X37: non | Y37: Vêtement de travail couvrant Gants de protection chimique vérifier les EPI recommandés de la FDS au préalable Rubrique 8 Lunette de sécurité. | Z37: 0.25 | AA37: Coresafety training : Sensibilisation à la manipulation des produits chimiques | AB37: 0.25 | AC37: FDS des produits utilisés Procedure substance dangeureuse COSH Alayse de risque produit chimique Seirich Respect strict des consignes de tri Attention aux mélange de déchets incompatibles Déclaration aux autorités des quantités par type de dechets Produits sur rétention | AD37: 0.25 | AE37: =100%-(Z37+AB37+AD37) -> 0.25 | AF37: =S37*AE37 -> 0.75 | AG37: =HLOOKUP($AF37,Cotation!$I$5:$M$10,'Risk Register'!U37,(TRUE)) -> F
B38: Exposition aux produits chimiques | C38: Stockage de produits chimiques | H38: x | I38: x | J38: x | M38: Projection de produits chimiques / Inhalation de vapeurs chimiques / brûlure | N38: 07. Risques liés aux produits chimiques, aux émissions et aux déchets | O38: Liquides et produits chimiques étiquetés dangereux / Cuve / IBC / Bidons | P38: Normal | Q38: 5 | R38: 2 | S38: =Q38+R38 -> 7 | T38: 3 | U38: =VLOOKUP($T38,Cotation!$G$6:$H$10,2,(FALSE)) -> 4 | V38: =HLOOKUP($S38,Cotation!$I$5:$M$10,'Risk Register'!U38,(TRUE)) -> S | W38: Compatibilité des matériaux et étiquetage des produits | X38: non | Y38: Vêtement de travail couvrant Gants de protection chimique vérifier les EPI recommandés de la FDS au préalable Rubrique 8 Lunette de sécurité. | Z38: 0.25 | AA38: Coresafety training : Sensibilisation à la manipulation des produits chimiques | AB38: 0.25 | AC38: FDS des produits utilisés Procedure substance dangeureuse COSH Alayse de risque produit chimique Seirich Respect strict des consignes de tri Attention aux mélange de déchets incompatibles Déclaration aux autorités des quantités par type de dechets Produits sur rétention | AD38: 0.25 | AE38: =100%-(Z38+AB38+AD38) -> 0.25 | AF38: =S38*AE38 -> 1.75 | AG38: =HLOOKUP($AF38,Cotation!$I$5:$M$10,'Risk Register'!U38,(TRUE)) -> F
B39: Exposition aux produits chimiques | C39: Utilisation de colle / vernis / peinture | G39: x | H39: x | I39: x | J39: x | M39: Projection de produits chimiques / Inhalation de vapeurs chimiques / brûlure | N39: 07. Risques liés aux produits chimiques, aux émissions et aux déchets | O39: Colle / vernis / peinture | P39: Normal | Q39: 4 | R39: 1 | S39: =Q39+R39 -> 5 | T39: 2 | U39: =VLOOKUP($T39,Cotation!$G$6:$H$10,2,(FALSE)) -> 5 | V39: =HLOOKUP($S39,Cotation!$I$5:$M$10,'Risk Register'!U39,(TRUE)) -> M | W39: Compatibilité des matériaux et étiquetage des produits | X39: non | Y39: Vêtement de travail couvrant Gants de protection chimique vérifier les EPI recommandés de la FDS au préalable Rubrique 8 Lunette de sécurité. | Z39: 0.25 | AA39: Coresafety training : Sensibilisation à la manipulation des produits chimiques | AB39: 0.25 | AC39: FDS des produits utilisés Procedure substance dangeureuse COSH Alayse de risque produit chimique Seirich Respect strict des consignes de tri Attention aux mélange de déchets incompatibles Déclaration aux autorités des quantités par type de dechets Produits sur rétention | AD39: 0.25 | AE39: =100%-(Z39+AB39+AD39) -> 0.25 | AF39: =S39*AE39 -> 1.25 | AG39: =HLOOKUP($AF39,Cotation!$I$5:$M$10,'Risk Register'!U39,(TRUE)) -> F
B40: Exposition aux produits chimiques | C40: Utilisation de solvant | G40: x | H40: x | I40: x | J40: x | M40: Projection de solvant / Inhalation de COV / brûlure / incendie | N40: 07. Risques liés aux produits chimiques, aux émissions et aux déchets | O40: Solvant | P40: Normal | Q40: 4 | R40: 1 | S40: =Q40+R40 -> 5 | T40: 3 | U40: =VLOOKUP($T40,Cotation!$G$6:$H$10,2,(FALSE)) -> 4 | V40: =HLOOKUP($S40,Cotation!$I$5:$M$10,'Risk Register'!U40,(TRUE)) -> M | W40: Compatibilité des matériaux et étiquetage des produits | X40: non | Y40: Vêtement de travail couvrant Gants de protection chimique vérifier les EPI recommandés de la FDS au préalable Rubrique 8 Lunette de sécurité. | Z40: 0.25 | AA40: Coresafety training : Sensibilisation à la manipulation des produits chimiques | AB40: 0.25 | AC40: FDS des produits utilisés Procedure substance dangeureuse COSH Alayse de risque produit chimique Seirich Respect strict des consignes de tri Attention aux mélange de déchets incompatibles Déclaration aux autorités des quantités par type de dechets Produits sur rétention | AD40: 0.25 | AE40: =100%-(Z40+AB40+AD40) -> 0.25 | AF40: =S40*AE40 -> 1.25 | AG40: =HLOOKUP($AF40,Cotation!$I$5:$M$10,'Risk Register'!U40,(TRUE)) -> F
B41: Exposition aux produits chimiques | C41: Utilisation de lubrifiant | G41: x | H41: x | I41: x | J41: x | M41: Projection de lubrifiant / Chute et glissade / incendie | N41: 07. Risques liés aux produits chimiques, aux émissions et aux déchets | O41: Lubrifiant | P41: Normal | Q41: 4 | R41: 1 | S41: =Q41+R41 -> 5 | T41: 2 | U41: =VLOOKUP($T41,Cotation!$G$6:$H$10,2,(FALSE)) -> 5 | V41: =HLOOKUP($S41,Cotation!$I$5:$M$10,'Risk Register'!U41,(TRUE)) -> M | W41: Compatibilité des matériaux et étiquetage des produits | X41: non | Y41: Vêtement de travail couvrant Gants de protection chimique vérifier les EPI recommandés de la FDS au préalable Rubrique 8 Lunette de sécurité. | Z41: 0.25 | AA41: Coresafety training : Sensibilisation à la manipulation des produits chimiques | AB41: 0.25 | AC41: FDS des produits utilisés Procedure substance dangeureuse COSH Alayse de risque produit chimique Seirich Respect strict des consignes de tri Attention aux mélange de déchets incompatibles Déclaration aux autorités des quantités par type de dechets Produits sur rétention | AD41: 0.25 | AE41: =100%-(Z41+AB41+AD41) -> 0.25 | AF41: =S41*AE41 -> 1.25 | AG41: =HLOOKUP($AF41,Cotation!$I$5:$M$10,'Risk Register'!U41,(TRUE)) -> F
B42: Exposition aux produits chimiques | C42: Remplissage de cuve en réactif chimique | H42: x | J42: x | M42: Projection de produits chimiques / Inhalation de vapeurs chimiques / brûlure | N42: 07. Risques liés aux produits chimiques, aux émissions et aux déchets | O42: Cuve de réactif chimique | P42: Normal | Q42: 1 | R42: 1 | S42: =Q42+R42 -> 2 | T42: 3 | U42: =VLOOKUP($T42,Cotation!$G$6:$H$10,2,(FALSE)) -> 4 | V42: =HLOOKUP($S42,Cotation!$I$5:$M$10,'Risk Register'!U42,(TRUE)) -> M | W42: Compatibilité des matériaux et étiquetage des produits / cuve double peau | X42: non | Y42: Vêtement de travail couvrant Gants de protection chimique vérifier les EPI recommandés de la FDS au préalable Rubrique 8 Lunette de sécurité. | Z42: 0.25 | AA42: Coresafety training : Sensibilisation à la manipulation des produits chimiques | AB42: 0.25 | AC42: FDS des produits utilisés Procedure substance dangeureuse COSH Alayse de risque produit chimique Seirich Respect strict des consignes de tri Attention aux mélange de déchets incompatibles Déclaration aux autorités des quantités par type de dechets Produits sur rétention | AD42: 0.25 | AE42: =100%-(Z42+AB42+AD42) -> 0.25 | AF42: =S42*AE42 -> 0.5 | AG42: =HLOOKUP($AF42,Cotation!$I$5:$M$10,'Risk Register'!U42,(TRUE)) -> F
...

Sheet Cotation
B2: Fréquence d'exposition au danger
B3: 1 | C3: Jamais à rarement | D3: Jamais exposé à 1 fois par an | F3: GRAVITE (G) | I3: Fréquence + probabilité
B4: 2 | C4: Quelque fois | D4: Exposé 1 fois par mois | I4: <2 | J4: 2<Class<4 | K4: 4<Class<6 | L4: 6<Class<8 | M4: 8<Class<10
B5: 3 | C5: De temps en temps | D5: Exposé 1 fois par semaine | H5: 1 | I5: 0 | J5: 2 | K5: 4 | L5: 6 | M5: 8
B6: 4 | C6: Régulièrement | D6: Exposé 1 fois par jour | F6: Catastrophique | G6: 5 | H6: 2 | I6: M | J6: S | K6: S | L6: C | M6: C
B7: 5 | C7: En continue | D7: Exposé plusieurs fois par jour | F7: Critique | G7: 4 | H7: 3 | I7: M | J7: M | K7: S | L7: S | M7: C
F8: Sérieuse ou Sévère | G8: 3 | H8: 4 | I8: F | J8: M | K8: M | L8: S | M8: S
B9: Probabilité d'occurrence d'un accident | F9: Conséquente | G9: 2 | H9: 5 | I9: F | J9: F | K9: M | L9: M | M9: S
B10: 1 | C10: Impossible à improbable | D10: Jamais rencontré | F10: Mineur | G10: 1 | H10: 6 | I10: F | J10: F | K10: F | L10: M | M10: M
B11: 2 | C11: Très peu probable | D11: Vu une fois
B12: 3 | C12: Peu probable | D12: Survenance dans l'année
B13: 4 | C13: Probable | D13: Survenance dans le mois
B14: 5 | C14: Très probable à certain | D14: Très fréquent à systématique
B16: Echelle de Gravité
B17: 1 | C17: Mineure | D17: Accident bénin / premiers soins
B18: 2 | C18: Modérée | D18: Lésion réversible nécessitant des soins hors hospitalisation
B19: 3 | C19: Significative | D19: Lésion réversible nécessitant une hospitalisation / Maladie proffesionnelle réversible / handicap temporaire
B20: 4 | C20: Critique | D20: Victime unique : Décès / Lésions irréversibles / Handicap permanent / Maladie professionnelle irréversible
B21: 5 | C21: Catastrophique | D21: Victimes multiples : Décès / Lésions irréversibles / Handicap permanent / Maladie professionnelle irréversible
B25: Equipement de protection
B26: 0 | C26: Pas d'équipement de protection, ni individuelle, ni collectif
B27: 0.1 | C27: Equipement de protection individuel adapté, porté et vérifié
B28: 0.25 | C28: Equipement de protection collectif installé, adapté et maintenu
B30: Formation
B31: 0 | C31: Aucune formation
B32: 0.1 | C32: Formation et sensibilisation réglementaire
B33: 0.25 | C33: Formation et sensibilisation complémentaire
B35: Mesures organisationnelles
B36: 0 | C36: Aucune
B37: 0.1 | C37: Présence de procédures et d'affichage
B38: 0.25 | C38: Connaissance et respect des procédures et des affichages
